Workbook

Sheet Read Me
A1: Women's Flat Track Derby Association
A2: IGRF & Standardized Stats Calculator
A3: February 2025 Release
A4: For use with January 1, 2023 The Rules of Flat Track Roller Derby
A6: Published by the Women's Flat Track Derby Association (WFTDA) 5900 Balcones Drive STE 4125, Austin, TX 78731, USA
A8: Modifications beyond those necessary for formatted printing are only allowed with the consent of the Women's Flat Track Derby Association. The Interleague Game Reporting Form and Standardized Stats Calculator ("StatsBook") and its contents may not be reproduced, distributed, or translated in whole or in part in any manner without the permission of the WFTDA.
A10: For Sanctioned games only:
A11: The host team follows the timeline and process for submitting required sanctioning data described in the WFTDA Sanctioning policy. The current WFTDA Sanctioning policy may be found at:
A12: https://resources.wftda.org/competition/wftda-competition-and-rankings/
A14: Instructions
A16: Detailed instructions for using the StatsBook are available in the StatsBook Manual, available at
A17: https://resources.wftda.org/competition/statsbook/
... A20: Please name your StatsBook file: STATS-YYYY-MM-DD_HostLeague_TeamName_vs_VisitorLeague_TeamName.
B21: Example: "STATS-2018-02-16_TosterCityRollerDerby_Allstars_vs_WaterCity_AllStars.xlsx"
A22: Please name your scanned IGRF: IGRF-YYYY-MM-DD_HostLeague_TeamName_vs_VisitorLeague_TeamName.
B23: Example: "IGRF-2018-02-16_TosterCityRollerDerby_Allstars_vs_WaterCity_AllStars.pdf"
A25: StatsBook/IGRF Instructions
B26: Submitting IGRFs
B27: Within 48 hours of game or tournament completion, the responsible party/host league representative should submit the following (scans or clear photos) to igrf@wftda.com
B28: 1. Both pages of the IGRF form, signed by both captains and head officials
B29: 2. Any Official Reviews should be tracked on the Official Review Form. If there are none, indicate this on the IGRF and you do not need to send in blank forms. If there are any, please indicate this on the IGRF and scan and submit the Official Review forms with the IGRF.
B30: 3. Expulsion-Suspension Forms: If there are no expulsions, indicate this on the IGRF and you do not need to send in blank forms. If there was an expulsion or expulsions, all parties should sign the form and provide email addresses in case WFTDA needs to follow up on the incident. Comments are not required and signatures do not indicate agreement with what other parties have written. See the WFTDA Expulsion and Suspension Policy for more information: https://resources.wftda.org/competition/wftda-competition-and-rankings/
B32: Submitting Statsbooks
B33: Please upload your completed StatsBooks to https://forms.gle/CMTPQYs6XhFHPkBE6 within two(2) weeks of the game or event. See Statsbook Manual for further instructions
A35: PLEASE NOTE: The host league is responsible for turning in the completed StatsBook and signed IGRF to WFTDA Sanctioning; however, Sanctioning will accept documents from either team. Captains from both teams should also receive a copy of the completed StatsBook and signed IGRF.
A36: Please do not abbreviate your league or team when naming documents for sanctioning.
A37: The StatsBook is provided by the WFTDA and contributors "as is" and any express or implied warranties, including, but not limited to, the implied warranties or merchantability and fitness for a particular purpose are disclaimed. In no event shall the WFTDA be liable for any direct, indirect, incidental, special, exemplary, or consequential damages (including, but not limited to, procurement of substitute goods or services; loss of use, data, or profits; or business interruption) however caused and on any theory of liability, whether in contract, strict liability, or tort (including negligence or otherwise) arising in any way out of the use of the StatsBook, even if advised of the possibility of such damage.

Sheet IGRF
A1: WFTDA Interleague Game Reporting Form (IGRF)
A2: Section 1. VENUE & ROSTERS (Complete BEFORE the game)
A3: Location: | B3: World Fair Park | I3: Knoxville | K3: TN | L3: 10
B4: VENUE NAME | I4: CITY | K4: ST/PRV | L4: GAME #
A5: Tournament/ Multi-Day Event: | B5: Honky Tonk Stomp | I5: Hard Knox Roller Derby
B6: TOURNAMENT/MULTI-DAY EVENT NAME | I6: HOST LEAGUE NAME
A7: Date: | B7: 46243 | G7: Start Time: | I7: 46243.75 | K7: Suspension: | L7: NO
A8: TEAM ROSTERS - List in order of Skater number
A9: H O M E T E A M | G9: V I S I T I N G T E A M
A10: LEAGUE | B10: Clarksville Roller Derby | G10: LEAGUE | I10: Nashville Roller Derby
A11: TEAM | B11: Rock Lobsters | G11: TEAM | I11: Nashville
A12: COLOR | G12: COLOR
A13: # of players | B13: Skater # | C13: Skater Name | G13: # of players | I13: Skater # | J13: Skater Name
A14: 1 | B14: 0 | C14: VHS | G14: 1 | I14: 00* | J14: Tonka Truck
A15: 2 | B15: 10 | C15: Mac Attack | G15: 2 | I15: 02* | J15: Creme BruSlay
A16: 3 | B16: 100 | C16: Beast Mode | G16: 3 | I16: 1004 | J16: kC
A17: 4 | B17: 102* | C17: Booty PopHer | G17: 4 | I17: 1031* | J17: Witch's Bruise
A18: 5 | B18: 1028* | C18: Danni-Lion | G18: 5 | I18: 107 | J18: Bettie Pain
A19: 6 | B19: 11 | C19: Pandora Nox | G19: 6 | I19: 113 | J19: Little Bull
A20: 7 | B20: 22 | C20: Atta Kontrol | G20: 7 | I20: 12 | J20: Katniss Evermean
A21: 8 | B21: 27 | C21: Shrike | G21: 8 | I21: 13 | J21: Hot Ghoul Shit
A22: 9 | B22: 321 | C22: Kentrolled Kaos | G22: 9 | I22: 20 | J22: Furiosa
A23: 10 | B23: 33 | C23: Sugaree | G23: 10 | I23: 21 | J23: The Bekkoning
A24: 11 | B24: 37* | C24: Mulan Bruise | G24: 11 | I24: 221 | J24: Rox N' Roll
A25: 12 | B25: 3713* | C25: Not Sorry | G25: 12 | I25: 262 | J25: Chaos
... A33: 20 | B33: 9 | C33: Billie Psycho | G33: 20 | I33: 911 | J33: Toxic Moxie
A34: Section 2. SCORE & PENALTIES (Complete DURING or IMMEDIATELY AFTER game)
A35: HOME TEAM | H35: VISITING TEAM
A36: Period 1 | B36: Points | C36: =IF(COUNT(Score!A4:A41)=0,"",Score!R42) | D36: Penalties | F36: =IF(COUNT(Score!A4:A41)=0,"",Penalties!L44) | H36: Period 1 | I36: Points | J36: =IF(COUNT(Score!T4:T41)=0,"",Score!AK42) | K36: Penalties | L36: =IF(COUNT(Score!T4:T41)=0,"",Penalties!AA44)
A37: Period 2 | B37: Points | C37: =IF(COUNT(Score!A46:A83)=0,"",Score!R84-C36) | D37: Penalties | F37: =IF(COUNT(Score!A46:A83)=0,"",Penalties!AN44) | H37: Period 2 | I37: Points | J37: =IF(COUNT(Score!T46:T83)=0,"",Score!AK84-J36) | K37: Penalties | L37: =IF(COUNT(Score!T46:T83)=0,"",Penalties!BC44)
A38: TOTAL POINTS: | C38: =IF(COUNT(Score!A4:A41)=0,"",SUM(C36:C37)) | D38: PENALTIES: | F38: =IF(COUNT(Score!A4:A41)=0,"",SUM(F36:F37)) | H38: TOTAL POINTS: | J38: =IF(COUNT(Score!T4:T41)=0,"",SUM(J36:J37)) | K38: PENALTIES: | L38: =IF(COUNT(Score!T4:T41)=0,"",SUM(L36:L37))
A39: The Official Score in this game required adjustment: | F39: Reason for OS adjustment:
A40: Expulsion/Suspension notes: | C40: Suspension was served by:
A41: Expulsion: | K41: Suspension: | L41: YES | NO
A43: Expulsion: | K43: Suspension: | L43: YES | NO
A45: Official Reviews | D45: YES | NO | G45: Expulsion Paperwork | K45: YES | NO
A46: If yes, submit scan of OR Paperwork with IGRF Scan | G46: If yes, submit scan of Expulsion Paperwork with IGRF
A47: Section 3. VERIFICATION (Complete IMMEDIATELY AFTER game)
A48: Home Team Captain | G48: Visiting Team Captain
A49: Skate Name: | G49: Skate Name:
...

Sheet Score
A1: =IF(IGRF!B11="","Home Team",IF(IGRF!B10=IGRF!I10,IGRF!B11,IF(IGRF!B10=IGRF!B11,IGRF!B10,IF(OR(IGRF!L3="A",IGRF!L3="B"),IGRF!B10&" "&IGRF!L3,IGRF!B10&" / "&IGRF!B11)))) -> Home Team | I1: =IF(ISBLANK(IGRF!$B$12), "", IGRF!$B$12) | K1: =IF(ISBLANK(IGRF!$B$7), "", IGRF!$B$7) | R1: 1 | T1: =IF(IGRF!$I$11="","Away Team",IF(IGRF!$B$10=IGRF!$I$10,IGRF!$I$11,IF(IGRF!$I$10=IGRF!$I$11,IGRF!$I$11,IF(OR(IGRF!$L$3="A",IGRF!$L$3="B"),IGRF!$I$10&" "&IGRF!$L$3,IGRF!$I$10&" / "&IGRF!$I$11)))) -> Away Team | AB1: =IF(ISBLANK(IGRF!$I$12), "", IGRF!$I$12) | AD1: =IF(ISBLANK(IGRF!$B$7), "", IGRF!$B$7) | AK1: 1
I2: Color | K2: Date | L2: Scorekeeper | O2: Jammer Ref | R2: =IF(ISBLANK(IGRF!$L$3), "", "GAME " & IGRF!$L$3) | AB2: Color | AD2: Date | AE2: Scorekeeper | AH2: Jammer Ref | AK2: =IF(ISBLANK(IGRF!$L$3), "", "GAME " & IGRF!$L$3)
A3: JAM | B3: Jammer's Number | C3: LOST | D3: LEAD | E3: CALL | F3: INJ. | G3: NI | H3: Trip 2 | I3: Trip 3 | J3: Trip 4 | K3: Trip 5 | L3: Trip 6 | M3: Trip 7 | N3: Trip 8 | O3: Trip 9 | P3: Trip 10 | Q3: Jam Total | R3: Game Total | S3: Trips | T3: JAM | U3: Jammer's Number | V3: LOST | W3: LEAD | X3: CALL | Y3: INJ. | Z3: NI | AA3: Trip 2 | AB3: Trip 3 | AC3: Trip 4 | AD3: Trip 5 | AE3: Trip 6 | AF3: Trip 7 | AG3: Trip 8 | AH3: Trip 9 | AI3: Trip 10 | AJ3: Jam Total | AK3: Game Total | AL3: Trips
A4: 1 | B4: 33 | G4: X | Q4: =IF(ISBLANK(A4),"",IF(ISBLANK(G4),SUM(H4:P4),0)) | R4: =IF(Q4="","",Q4+'OS Offset'!B4) | S4: =IF(G4="X",0,COUNT(H4:P4)) -> 0 | T4: 1 | U4: 12 | W4: X | X4: X | AA4: 4 | AB4: 4 | AC4: 4 | AJ4: =IF(ISBLANK(T4),"",IF(ISBLANK(Z4),SUM(AA4:AI4),0)) | AK4: =IF(AJ4="","",AJ4+'OS Offset'!I4) | AL4: =IF(Z4="X",0,COUNT(AA4:AI4)) -> 0
A5: SP | B5: 9 | H5: 0 | Q5: =IF(ISBLANK(A5),"",IF(ISBLANK(G5),SUM(H5:P5),0)) | R5: =IF(Q5="","",Q5+R4+'OS Offset'!B5) | S5: =IF(G5="X",0,COUNT(H5:P5)) -> 0 | T5: SP* | AJ5: =IF(ISBLANK(T5),"",IF(ISBLANK(Z5),SUM(AA5:AI5),0)) | AK5: =IF(AJ5="","",AJ5+AK4+'OS Offset'!I5) | AL5: =IF(Z5="X",0,COUNT(AA5:AI5)) -> 0
A6: 2 | B6: 765 | D6: X | E6: X | H6: 4 | I6: 4 | Q6: =IF(ISBLANK(A6),"",IF(ISBLANK(G6),SUM(H6:P6),0)) | R6: =IF(Q6="","",Q6+R5+'OS Offset'!B6) | S6: =IF(G6="X",0,COUNT(H6:P6)) -> 0 | T6: 2 | U6: 643 | Z6: X | AJ6: =IF(ISBLANK(T6),"",IF(ISBLANK(Z6),SUM(AA6:AI6),0)) | AK6: =IF(AJ6="","",AJ6+AK5+'OS Offset'!I6) | AL6: =IF(Z6="X",0,COUNT(AA6:AI6)) -> 0
A7: SP* | Q7: =IF(ISBLANK(A7),"",IF(ISBLANK(G7),SUM(H7:P7),0)) | R7: =IF(Q7="","",Q7+R6+'OS Offset'!B7) | S7: =IF(G7="X",0,COUNT(H7:P7)) -> 0 | T7: SP | U7: 262 | AA7: 0 | AJ7: =IF(ISBLANK(T7),"",IF(ISBLANK(Z7),SUM(AA7:AI7),0)) | AK7: =IF(AJ7="","",AJ7+AK6+'OS Offset'!I7) | AL7: =IF(Z7="X",0,COUNT(AA7:AI7)) -> 0
A8: 3 | B8: 77 | H8: 0 | Q8: =IF(ISBLANK(A8),"",IF(ISBLANK(G8),SUM(H8:P8),0)) | R8: =IF(Q8="","",Q8+R7+'OS Offset'!B8) | S8: =IF(G8="X",0,COUNT(H8:P8)) -> 0 | T8: 3 | U8: 20 | W8: X | X8: X | AA8: 4 | AJ8: =IF(ISBLANK(T8),"",IF(ISBLANK(Z8),SUM(AA8:AI8),0)) | AK8: =IF(AJ8="","",AJ8+AK7+'OS Offset'!I8) | AL8: =IF(Z8="X",0,COUNT(AA8:AI8)) -> 0
A9: 4 | B9: 66 | D9: X | E9: X | H9: 4 | I9: 3 | Q9: =IF(ISBLANK(A9),"",IF(ISBLANK(G9),SUM(H9:P9),0)) | R9: =IF(Q9="","",Q9+R8+'OS Offset'!B9) | S9: =IF(G9="X",0,COUNT(H9:P9)) -> 0 | T9: 4 | U9: 63 | AA9: 0 | AJ9: =IF(ISBLANK(T9),"",IF(ISBLANK(Z9),SUM(AA9:AI9),0)) | AK9: =IF(AJ9="","",AJ9+AK8+'OS Offset'!I9) | AL9: =IF(Z9="X",0,COUNT(AA9:AI9)) -> 0
A10: 5 | B10: 33 | H10: 0 | Q10: =IF(ISBLANK(A10),"",IF(ISBLANK(G10),SUM(H10:P10),0)) | R10: =IF(Q10="","",Q10+R9+'OS Offset'!B10) | S10: =IF(G10="X",0,COUNT(H10:P10)) -> 0 | T10: 5 | U10: 12 | W10: X | X10: X | AA10: 4 | AB10: 0 | AJ10: =IF(ISBLANK(T10),"",IF(ISBLANK(Z10),SUM(AA10:AI10),0)) | AK10: =IF(AJ10="","",AJ10+AK9+'OS Offset'!I10) | AL10: =IF(Z10="X",0,COUNT(AA10:AI10)) -> 0
A11: 6 | B11: 765 | H11: 0 | Q11: =IF(ISBLANK(A11),"",IF(ISBLANK(G11),SUM(H11:P11),0)) | R11: =IF(Q11="","",Q11+R10+'OS Offset'!B11) | S11: =IF(G11="X",0,COUNT(H11:P11)) -> 0 | T11: 6 | U11: 643 | W11: X | X11: X | AA11: 2 | AJ11: =IF(ISBLANK(T11),"",IF(ISBLANK(Z11),SUM(AA11:AI11),0)) | AK11: =IF(AJ11="","",AJ11+AK10+'OS Offset'!I11) | AL11: =IF(Z11="X",0,COUNT(AA11:AI11)) -> 0
A12: 7 | B12: 77 | H12: 0 | Q12: =IF(ISBLANK(A12),"",IF(ISBLANK(G12),SUM(H12:P12),0)) | R12: =IF(Q12="","",Q12+R11+'OS Offset'!B12) | S12: =IF(G12="X",0,COUNT(H12:P12)) -> 0 | T12: 7 | U12: 20 | W12: X | X12: X | AA12: 4 | AJ12: =IF(ISBLANK(T12),"",IF(ISBLANK(Z12),SUM(AA12:AI12),0)) | AK12: =IF(AJ12="","",AJ12+AK11+'OS Offset'!I12) | AL12: =IF(Z12="X",0,COUNT(AA12:AI12)) -> 0
A13: 8 | B13: 66 | D13: X | E13: X | H13: 4 | Q13: =IF(ISBLANK(A13),"",IF(ISBLANK(G13),SUM(H13:P13),0)) | R13: =IF(Q13="","",Q13+R12+'OS Offset'!B13) | S13: =IF(G13="X",0,COUNT(H13:P13)) -> 0 | T13: 8 | U13: 63 | AA13: 0 | AJ13: =IF(ISBLANK(T13),"",IF(ISBLANK(Z13),SUM(AA13:AI13),0)) | AK13: =IF(AJ13="","",AJ13+AK12+'OS Offset'!I13) | AL13: =IF(Z13="X",0,COUNT(AA13:AI13)) -> 0
A14: 9 | B14: 33 | H14: 0 | Q14: =IF(ISBLANK(A14),"",IF(ISBLANK(G14),SUM(H14:P14),0)) | R14: =IF(Q14="","",Q14+R13+'OS Offset'!B14) | S14: =IF(G14="X",0,COUNT(H14:P14)) -> 0 | T14: 9 | U14: 12 | W14: X | X14: X | AA14: 3 | AJ14: =IF(ISBLANK(T14),"",IF(ISBLANK(Z14),SUM(AA14:AI14),0)) | AK14: =IF(AJ14="","",AJ14+AK13+'OS Offset'!I14) | AL14: =IF(Z14="X",0,COUNT(AA14:AI14)) -> 0
A15: 10 | B15: 765 | C15: X | D15: X | H15: 3 | Q15: =IF(ISBLANK(A15),"",IF(ISBLANK(G15),SUM(H15:P15),0)) | R15: =IF(Q15="","",Q15+R14+'OS Offset'!B15) | S15: =IF(G15="X",0,COUNT(H15:P15)) -> 0 | T15: 10 | U15: 643 | Z15: X | AJ15: =IF(ISBLANK(T15),"",IF(ISBLANK(Z15),SUM(AA15:AI15),0)) | AK15: =IF(AJ15="","",AJ15+AK14+'OS Offset'!I15) | AL15: =IF(Z15="X",0,COUNT(AA15:AI15)) -> 0
A16: SP* | Q16: =IF(ISBLANK(A16),"",IF(ISBLANK(G16),SUM(H16:P16),0)) | R16: =IF(Q16="","",Q16+R15+'OS Offset'!B16) | S16: =IF(G16="X",0,COUNT(H16:P16)) -> 0 | T16: SP | U16: 262 | AA16: 4 | AJ16: =IF(ISBLANK(T16),"",IF(ISBLANK(Z16),SUM(AA16:AI16),0)) | AK16: =IF(AJ16="","",AJ16+AK15+'OS Offset'!I16) | AL16: =IF(Z16="X",0,COUNT(AA16:AI16)) -> 0
A17: 11 | B17: 77 | H17: 0 | Q17: =IF(ISBLANK(A17),"",IF(ISBLANK(G17),SUM(H17:P17),0)) | R17: =IF(Q17="","",Q17+R16+'OS Offset'!B17) | S17: =IF(G17="X",0,COUNT(H17:P17)) -> 0 | T17: 11 | U17: 20 | W17: X | X17: X | AA17: 4 | AJ17: =IF(ISBLANK(T17),"",IF(ISBLANK(Z17),SUM(AA17:AI17),0)) | AK17: =IF(AJ17="","",AJ17+AK16+'OS Offset'!I17) | AL17: =IF(Z17="X",0,COUNT(AA17:AI17)) -> 0
A18: 12 | B18: 66 | H18: 0 | Q18: =IF(ISBLANK(A18),"",IF(ISBLANK(G18),SUM(H18:P18),0)) | R18: =IF(Q18="","",Q18+R17+'OS Offset'!B18) | S18: =IF(G18="X",0,COUNT(H18:P18)) -> 0 | T18: 12 | U18: 12 | W18: X | X18: X | AA18: 0 | AJ18: =IF(ISBLANK(T18),"",IF(ISBLANK(Z18),SUM(AA18:AI18),0)) | AK18: =IF(AJ18="","",AJ18+AK17+'OS Offset'!I18) | AL18: =IF(Z18="X",0,COUNT(AA18:AI18)) -> 0
A19: 13 | B19: 33 | G19: X | Q19: =IF(ISBLANK(A19),"",IF(ISBLANK(G19),SUM(H19:P19),0)) | R19: =IF(Q19="","",Q19+R18+'OS Offset'!B19) | S19: =IF(G19="X",0,COUNT(H19:P19)) -> 0 | T19: 13 | U19: 643 | W19: X | X19: X | AA19: 4 | AJ19: =IF(ISBLANK(T19),"",IF(ISBLANK(Z19),SUM(AA19:AI19),0)) | AK19: =IF(AJ19="","",AJ19+AK18+'OS Offset'!I19) | AL19: =IF(Z19="X",0,COUNT(AA19:AI19)) -> 0
A20: SP | B20: 10 | H20: 0 | Q20: =IF(ISBLANK(A20),"",IF(ISBLANK(G20),SUM(H20:P20),0)) | R20: =IF(Q20="","",Q20+R19+'OS Offset'!B20) | S20: =IF(G20="X",0,COUNT(H20:P20)) -> 0 | T20: SP* | AJ20: =IF(ISBLANK(T20),"",IF(ISBLANK(Z20),SUM(AA20:AI20),0)) | AK20: =IF(AJ20="","",AJ20+AK19+'OS Offset'!I20) | AL20: =IF(Z20="X",0,COUNT(AA20:AI20)) -> 0
A21: 14 | B21: 765 | G21: X | Q21: =IF(ISBLANK(A21),"",IF(ISBLANK(G21),SUM(H21:P21),0)) | R21: =IF(Q21="","",Q21+R20+'OS Offset'!B21) | S21: =IF(G21="X",0,COUNT(H21:P21)) -> 0 | T21: 14 | U21: 20 | W21: X | X21: X | AA21: 4 | AB21: 4 | AJ21: =IF(ISBLANK(T21),"",IF(ISBLANK(Z21),SUM(AA21:AI21),0)) | AK21: =IF(AJ21="","",AJ21+AK20+'OS Offset'!I21) | AL21: =IF(Z21="X",0,COUNT(AA21:AI21)) -> 0
A22: 15 | B22: 77 | D22: X | E22: X | H22: 4 | I22: 4 | Q22: =IF(ISBLANK(A22),"",IF(ISBLANK(G22),SUM(H22:P22),0)) | R22: =IF(Q22="","",Q22+R21+'OS Offset'!B22) | S22: =IF(G22="X",0,COUNT(H22:P22)) -> 0 | T22: 15 | U22: 63 | Z22: X | AJ22: =IF(ISBLANK(T22),"",IF(ISBLANK(Z22),SUM(AA22:AI22),0)) | AK22: =IF(AJ22="","",AJ22+AK21+'OS Offset'!I22) | AL22: =IF(Z22="X",0,COUNT(AA22:AI22)) -> 0
A23: SP* | Q23: =IF(ISBLANK(A23),"",IF(ISBLANK(G23),SUM(H23:P23),0)) | R23: =IF(Q23="","",Q23+R22+'OS Offset'!B23) | S23: =IF(G23="X",0,COUNT(H23:P23)) -> 0 | T23: SP | U23: 56 | AA23: 4 | AB23: 0 | AJ23: =IF(ISBLANK(T23),"",IF(ISBLANK(Z23),SUM(AA23:AI23),0)) | AK23: =IF(AJ23="","",AJ23+AK22+'OS Offset'!I23) | AL23: =IF(Z23="X",0,COUNT(AA23:AI23)) -> 0
A24: 16 | B24: 66 | D24: X | E24: X | H24: 4 | Q24: =IF(ISBLANK(A24),"",IF(ISBLANK(G24),SUM(H24:P24),0)) | R24: =IF(Q24="","",Q24+R23+'OS Offset'!B24) | S24: =IF(G24="X",0,COUNT(H24:P24)) -> 0 | T24: 16 | U24: 12 | AA24: 4 | AJ24: =IF(ISBLANK(T24),"",IF(ISBLANK(Z24),SUM(AA24:AI24),0)) | AK24: =IF(AJ24="","",AJ24+AK23+'OS Offset'!I24) | AL24: =IF(Z24="X",0,COUNT(AA24:AI24)) -> 0
A25: 17 | B25: 33 | H25: 0 | Q25: =IF(ISBLANK(A25),"",IF(ISBLANK(G25),SUM(H25:P25),0)) | R25: =IF(Q25="","",Q25+R24+'OS Offset'!B25) | S25: =IF(G25="X",0,COUNT(H25:P25)) -> 0 | T25: 17 | U25: 643 | W25: X | X25: X | Z25: X | AJ25: =IF(ISBLANK(T25),"",IF(ISBLANK(Z25),SUM(AA25:AI25),0)) | AK25: =IF(AJ25="","",AJ25+AK24+'OS Offset'!I25) | AL25: =IF(Z25="X",0,COUNT(AA25:AI25)) -> 0
A26: 18 | B26: 765 | D26: X | E26: X | H26: 4 | Q26: =IF(ISBLANK(A26),"",IF(ISBLANK(G26),SUM(H26:P26),0)) | R26: =IF(Q26="","",Q26+R25+'OS Offset'!B26) | S26: =IF(G26="X",0,COUNT(H26:P26)) -> 0 | T26: 18 | U26: 20 | AA26: 0 | AJ26: =IF(ISBLANK(T26),"",IF(ISBLANK(Z26),SUM(AA26:AI26),0)) | AK26: =IF(AJ26="","",AJ26+AK25+'OS Offset'!I26) | AL26: =IF(Z26="X",0,COUNT(AA26:AI26)) -> 0
A27: 19 | B27: 77 | G27: X | Q27: =IF(ISBLANK(A27),"",IF(ISBLANK(G27),SUM(H27:P27),0)) | R27: =IF(Q27="","",Q27+R26+'OS Offset'!B27) | S27: =IF(G27="X",0,COUNT(H27:P27)) -> 0 | T27: 19 | U27: 63 | W27: X | X27: X | AA27: 2 | AJ27: =IF(ISBLANK(T27),"",IF(ISBLANK(Z27),SUM(AA27:AI27),0)) | AK27: =IF(AJ27="","",AJ27+AK26+'OS Offset'!I27) | AL27: =IF(Z27="X",0,COUNT(AA27:AI27)) -> 0
A28: 20 | B28: 66 | D28: X | E28: X | H28: 4 | I28: 0 | Q28: =IF(ISBLANK(A28),"",IF(ISBLANK(G28),SUM(H28:P28),0)) | R28: =IF(Q28="","",Q28+R27+'OS Offset'!B28) | S28: =IF(G28="X",0,COUNT(H28:P28)) -> 0 | T28: 20 | U28: 12 | AA28: 4 | AB28: 4 | AJ28: =IF(ISBLANK(T28),"",IF(ISBLANK(Z28),SUM(AA28:AI28),0)) | AK28: =IF(AJ28="","",AJ28+AK27+'OS Offset'!I28) | AL28: =IF(Z28="X",0,COUNT(AA28:AI28)) -> 0
A29: 21 | B29: 765 | D29: X | E29: X | H29: 1 | Q29: =IF(ISBLANK(A29),"",IF(ISBLANK(G29),SUM(H29:P29),0)) | R29: =IF(Q29="","",Q29+R28+'OS Offset'!B29) | S29: =IF(G29="X",0,COUNT(H29:P29)) -> 0 | T29: 21 | U29: 643 | AA29: 0 | AJ29: =IF(ISBLANK(T29),"",IF(ISBLANK(Z29),SUM(AA29:AI29),0)) | AK29: =IF(AJ29="","",AJ29+AK28+'OS Offset'!I29) | AL29: =IF(Z29="X",0,COUNT(AA29:AI29)) -> 0
A30: 22 | B30: 33 | D30: X | E30: X | H30: 4 | I30: 4 | J30: 0 | Q30: =IF(ISBLANK(A30),"",IF(ISBLANK(G30),SUM(H30:P30),0)) | R30: =IF(Q30="","",Q30+R29+'OS Offset'!B30) | S30: =IF(G30="X",0,COUNT(H30:P30)) -> 0 | T30: 22 | U30: 20 | Z30: X | AJ30: =IF(ISBLANK(T30),"",IF(ISBLANK(Z30),SUM(AA30:AI30),0)) | AK30: =IF(AJ30="","",AJ30+AK29+'OS Offset'!I30) | AL30: =IF(Z30="X",0,COUNT(AA30:AI30)) -> 0
Q31: =IF(ISBLANK(A31),"",IF(ISBLANK(G31),SUM(H31:P31),0)) | R31: =IF(Q31="","",Q31+R30+'OS Offset'!B31) | S31: =IF(G31="X",0,COUNT(H31:P31)) -> 0 | AJ31: =IF(ISBLANK(T31),"",IF(ISBLANK(Z31),SUM(AA31:AI31),0)) | AK31: =IF(AJ31="","",AJ31+AK30+'OS Offset'!I31) | AL31: =IF(Z31="X",0,COUNT(AA31:AI31)) -> 0
Q32: =IF(ISBLANK(A32),"",IF(ISBLANK(G32),SUM(H32:P32),0)) | R32: =IF(Q32="","",Q32+R31+'OS Offset'!B32) | S32: =IF(G32="X",0,COUNT(H32:P32)) -> 0 | AJ32: =IF(ISBLANK(T32),"",IF(ISBLANK(Z32),SUM(AA32:AI32),0)) | AK32: =IF(AJ32="","",AJ32+AK31+'OS Offset'!I32) | AL32: =IF(Z32="X",0,COUNT(AA32:AI32)) -> 0
Q33: =IF(ISBLANK(A33),"",IF(ISBLANK(G33),SUM(H33:P33),0)) | R33: =IF(Q33="","",Q33+R32+'OS Offset'!B33) | S33: =IF(G33="X",0,COUNT(H33:P33)) -> 0 | AJ33: =IF(ISBLANK(T33),"",IF(ISBLANK(Z33),SUM(AA33:AI33),0)) | AK33: =IF(AJ33="","",AJ33+AK32+'OS Offset'!I33) | AL33: =IF(Z33="X",0,COUNT(AA33:AI33)) -> 0
Q34: =IF(ISBLANK(A34),"",IF(ISBLANK(G34),SUM(H34:P34),0)) | R34: =IF(Q34="","",Q34+R33+'OS Offset'!B34) | S34: =IF(G34="X",0,COUNT(H34:P34)) -> 0 | AJ34: =IF(ISBLANK(T34),"",IF(ISBLANK(Z34),SUM(AA34:AI34),0)) | AK34: =IF(AJ34="","",AJ34+AK33+'OS Offset'!I34) | AL34: =IF(Z34="X",0,COUNT(AA34:AI34)) -> 0
Q35: =IF(ISBLANK(A35),"",IF(ISBLANK(G35),SUM(H35:P35),0)) | R35: =IF(Q35="","",Q35+R34+'OS Offset'!B35) | S35: =IF(G35="X",0,COUNT(H35:P35)) -> 0 | AJ35: =IF(ISBLANK(T35),"",IF(ISBLANK(Z35),SUM(AA35:AI35),0)) | AK35: =IF(AJ35="","",AJ35+AK34+'OS Offset'!I35) | AL35: =IF(Z35="X",0,COUNT(AA35:AI35)) -> 0
Q36: =IF(ISBLANK(A36),"",IF(ISBLANK(G36),SUM(H36:P36),0)) | R36: =IF(Q36="","",Q36+R35+'OS Offset'!B36) | S36: =IF(G36="X",0,COUNT(H36:P36)) -> 0 | AJ36: =IF(ISBLANK(T36),"",IF(ISBLANK(Z36),SUM(AA36:AI36),0)) | AK36: =IF(AJ36="","",AJ36+AK35+'OS Offset'!I36) | AL36: =IF(Z36="X",0,COUNT(AA36:AI36)) -> 0
Q37: =IF(ISBLANK(A37),"",IF(ISBLANK(G37),SUM(H37:P37),0)) | R37: =IF(Q37="","",Q37+R36+'OS Offset'!B37) | S37: =IF(G37="X",0,COUNT(H37:P37)) -> 0 | AJ37: =IF(ISBLANK(T37),"",IF(ISBLANK(Z37),SUM(AA37:AI37),0)) | AK37: =IF(AJ37="","",AJ37+AK36+'OS Offset'!I37) | AL37: =IF(Z37="X",0,COUNT(AA37:AI37)) -> 0
Q38: =IF(ISBLANK(A38),"",IF(ISBLANK(G38),SUM(H38:P38),0)) | R38: =IF(Q38="","",Q38+R37+'OS Offset'!B38) | S38: =IF(G38="X",0,COUNT(H38:P38)) -> 0 | AJ38: =IF(ISBLANK(T38),"",IF(ISBLANK(Z38),SUM(AA38:AI38),0)) | AK38: =IF(AJ38="","",AJ38+AK37+'OS Offset'!I38) | AL38: =IF(Z38="X",0,COUNT(AA38:AI38)) -> 0
Q39: =IF(ISBLANK(A39),"",IF(ISBLANK(G39),SUM(H39:P39),0)) | R39: =IF(Q39="","",Q39+R38+'OS Offset'!B39) | S39: =IF(G39="X",0,COUNT(H39:P39)) -> 0 | AJ39: =IF(ISBLANK(T39),"",IF(ISBLANK(Z39),SUM(AA39:AI39),0)) | AK39: =IF(AJ39="","",AJ39+AK38+'OS Offset'!I39) | AL39: =IF(Z39="X",0,COUNT(AA39:AI39)) -> 0
Q40: =IF(ISBLANK(A40),"",IF(ISBLANK(G40),SUM(H40:P40),0)) | R40: =IF(Q40="","",Q40+R39+'OS Offset'!B40) | S40: =IF(G40="X",0,COUNT(H40:P40)) -> 0 | AJ40: =IF(ISBLANK(T40),"",IF(ISBLANK(Z40),SUM(AA40:AI40),0)) | AK40: =IF(AJ40="","",AJ40+AK39+'OS Offset'!I40) | AL40: =IF(Z40="X",0,COUNT(AA40:AI40)) -> 0
...

Sheet Penalties
A1: =Score!$A$1 -> Home Team | I1: =IF(ISBLANK(IGRF!$B$12), "", IGRF!$B$12) | L1: =IF(ISBLANK(IGRF!$B$7), "", IGRF!$B$7) | Q1: =Score!$T$1 -> Away Team | Z1: =IF(ISBLANK(IGRF!$I$12), "", IGRF!$I$12) | AB1: 1 | AC1: =A1 -> Home Team | AK1: =I1 | AN1: =L1 | AS1: =Q1 -> Away Team | BB1: =Z1 | BD1: 2
I2: Color | L2: Date | N2: Penalty Tracker | Z2: Color | AB2: =IF(ISBLANK(IGRF!$L$3), "", "GAME " & IGRF!$L$3) | AK2: Color | AN2: Date | AP2: Penalty Tracker | BB2: Color | BD2: =AB2
A3: # | B3: PENALTY / JAM # | K3: FO/EXP | L3: TOTAL | M3: NOTES | P3: # | Q3: PENALTY / JAM # | Z3: FO/EXP | AA3: TOTAL | AB3: Codes | AC3: # | AD3: PENALTY / JAM # | AM3: FO/EXP | AN3: TOTAL | AO3: NOTES | AR3: # | AS3: PENALTY / JAM # | BB3: FO/EXP | BC3: TOTAL | BD3: Codes
A4: =IF(IGRF!B14="","",IGRF!B14) | B4: M | C4: G | D4: M | E4: P | F4: M | L4: =IF(COUNTA(B4:J4)=0,"",COUNTA(B4:J4)) | M4: 1 | P4: =IF(IGRF!I14="","",IGRF!I14) | AA4: =IF(COUNTA(Q4:Y4)=0,"",COUNTA(Q4:Y4)) | AB4: G | AC4: =IF(IGRF!B14="","",IGRF!B14) | AN4: =IF(COUNTA(AD4:AL4)=0,"",COUNTA(AD4:AL4)) | AO4: 1 | AR4: =IF(IGRF!I14="","",IGRF!I14) | BC4: =IF(COUNTA(AS4:BA4)=0,"",COUNTA(AS4:BA4)) | BD4: G
B5: 4 | C5: 4 | D5: 10 | E5: 10 | F5: 13 | M5: 2 | AB5: (Gross) | AO5: 2 | BD5: (Gross)
A6: =IF(IGRF!B15="","",IGRF!B15) | B6: P | C6: C | D6: P | L6: =IF(COUNTA(B6:J6)=0,"",COUNTA(B6:J6)) | M6: 3 | O6: 3 | P6: =IF(IGRF!I15="","",IGRF!I15) | AA6: =IF(COUNTA(Q6:Y6)=0,"",COUNTA(Q6:Y6)) | AB6: Misconduct | AC6: =IF(IGRF!B15="","",IGRF!B15) | AG6: D | AN6: =IF(COUNTA(AD6:AL6)=0,"",COUNTA(AD6:AL6)) | AO6: 3 | AR6: =IF(IGRF!I15="","",IGRF!I15) | BC6: =IF(COUNTA(AS6:BA6)=0,"",COUNTA(AS6:BA6)) | BD6: Misconduct
B7: 2 | C7: 15 | D7: 20 | M7: 4 | O7: 4 | AB7: Insubordination | AG7: 17 | AO7: 4 | BD7: Insubordination
A8: =IF(IGRF!B16="","",IGRF!B16) | B8: P | L8: =IF(COUNTA(B8:J8)=0,"",COUNTA(B8:J8)) | M8: 5 | O8: 5 | P8: =IF(IGRF!I16="","",IGRF!I16) | Q8: C | R8: P | S8: D | AA8: =IF(COUNTA(Q8:Y8)=0,"",COUNTA(Q8:Y8)) | AB8: A | AC8: =IF(IGRF!B16="","",IGRF!B16) | AE8: M | AF8: C | AN8: =IF(COUNTA(AD8:AL8)=0,"",COUNTA(AD8:AL8)) | AO8: 5 | AR8: =IF(IGRF!I16="","",IGRF!I16) | AV8: A | AW8: P | AX8: D | AY8: I | AZ8: P | BB8: FO | BC8: =IF(COUNTA(AS8:BA8)=0,"",COUNTA(AS8:BA8)) | BD8: A
B9: 5 | M9: 6 | O9: 6 | Q9: 3 | R9: 15 | S9: 19 | AB9: High Block | AE9: 3 | AF9: 4 | AO9: 6 | AV9: 4 | AW9: 14 | AX9: 16 | AY9: 18 | AZ9: 18 | BB9: 18 | BD9: High Block
A10: =IF(IGRF!B17="","",IGRF!B17) | L10: =IF(COUNTA(B10:J10)=0,"",COUNTA(B10:J10)) | M10: 7 | O10: 7 | P10: =IF(IGRF!I17="","",IGRF!I17) | AA10: =IF(COUNTA(Q10:Y10)=0,"",COUNTA(Q10:Y10)) | AB10: B | AC10: =IF(IGRF!B17="","",IGRF!B17) | AN10: =IF(COUNTA(AD10:AL10)=0,"",COUNTA(AD10:AL10)) | AO10: 7 | AR10: =IF(IGRF!I17="","",IGRF!I17) | BC10: =IF(COUNTA(AS10:BA10)=0,"",COUNTA(AS10:BA10)) | BD10: B
M11: 8 | O11: 8 | AB11: Back Block | AO11: 8 | BD11: Back Block
A12: =IF(IGRF!B18="","",IGRF!B18) | L12: =IF(COUNTA(B12:J12)=0,"",COUNTA(B12:J12)) | M12: 9 | O12: 9 | P12: =IF(IGRF!I18="","",IGRF!I18) | Q12: D | R12: P | S12: L | T12: P | U12: ? | AA12: =IF(COUNTA(Q12:Y12)=0,"",COUNTA(Q12:Y12)) | AB12: L | AC12: =IF(IGRF!B18="","",IGRF!B18) | AN12: =IF(COUNTA(AD12:AL12)=0,"",COUNTA(AD12:AL12)) | AO12: 9 | AR12: =IF(IGRF!I18="","",IGRF!I18) | BC12: =IF(COUNTA(AS12:BA12)=0,"",COUNTA(AS12:BA12)) | BD12: L
M13: 10 | O13: 10 | Q13: 2 | R13: 8 | S13: 9 | T13: 22 | U13: 22 | AB13: Low Block | AO13: 10 | BD13: Low Block
A14: =IF(IGRF!B19="","",IGRF!B19) | L14: =IF(COUNTA(B14:J14)=0,"",COUNTA(B14:J14)) | M14: 11 | O14: 11 | P14: =IF(IGRF!I19="","",IGRF!I19) | Q14: D | R14: M | AA14: =IF(COUNTA(Q14:Y14)=0,"",COUNTA(Q14:Y14)) | AB14: E | AC14: =IF(IGRF!B19="","",IGRF!B19) | AD14: F | AN14: =IF(COUNTA(AD14:AL14)=0,"",COUNTA(AD14:AL14)) | AO14: 11 | AR14: =IF(IGRF!I19="","",IGRF!I19) | AU14: P | AV14: C | BC14: =IF(COUNTA(AS14:BA14)=0,"",COUNTA(AS14:BA14)) | BD14: E
M15: 12 | O15: 12 | Q15: 18 | R15: 22 | AB15: Leg Block | AD15: 18 | AO15: 12 | AU15: 11 | AV15: 12 | BD15: Leg Block
A16: =IF(IGRF!B20="","",IGRF!B20) | L16: =IF(COUNTA(B16:J16)=0,"",COUNTA(B16:J16)) | M16: 13 | O16: 13 | P16: =IF(IGRF!I20="","",IGRF!I20) | AA16: =IF(COUNTA(Q16:Y16)=0,"",COUNTA(Q16:Y16)) | AB16: F | AC16: =IF(IGRF!B20="","",IGRF!B20) | AN16: =IF(COUNTA(AD16:AL16)=0,"",COUNTA(AD16:AL16)) | AO16: 13 | AR16: =IF(IGRF!I20="","",IGRF!I20) | BC16: =IF(COUNTA(AS16:BA16)=0,"",COUNTA(AS16:BA16)) | BD16: F
M17: 14 | O17: 14 | AB17: Forearms | AO17: 14 | BD17: Forearms
A18: =IF(IGRF!B21="","",IGRF!B21) | B18: M | L18: =IF(COUNTA(B18:J18)=0,"",COUNTA(B18:J18)) | M18: 15 | O18: 15 | P18: =IF(IGRF!I21="","",IGRF!I21) | Q18: D | R18: C | AA18: =IF(COUNTA(Q18:Y18)=0,"",COUNTA(Q18:Y18)) | AB18: H | AC18: =IF(IGRF!B21="","",IGRF!B21) | AN18: =IF(COUNTA(AD18:AL18)=0,"",COUNTA(AD18:AL18)) | AO18: 15 | AR18: =IF(IGRF!I21="","",IGRF!I21) | AU18: D | BC18: =IF(COUNTA(AS18:BA18)=0,"",COUNTA(AS18:BA18)) | BD18: H
B19: 17 | M19: 16 | O19: 16 | Q19: 3 | R19: 15 | AB19: Head Block | AO19: 16 | AU19: 8 | BD19: Head Block
A20: =IF(IGRF!B22="","",IGRF!B22) | B20: P | L20: =IF(COUNTA(B20:J20)=0,"",COUNTA(B20:J20)) | M20: 17 | O20: 17 | P20: =IF(IGRF!I22="","",IGRF!I22) | Q20: C | AA20: =IF(COUNTA(Q20:Y20)=0,"",COUNTA(Q20:Y20)) | AB20: M | AC20: =IF(IGRF!B22="","",IGRF!B22) | AE20: M | AF20: M | AG20: M | AH20: M | AN20: =IF(COUNTA(AD20:AL20)=0,"",COUNTA(AD20:AL20)) | AO20: 17 | AR20: =IF(IGRF!I22="","",IGRF!I22) | AT20: X | BC20: =IF(COUNTA(AS20:BA20)=0,"",COUNTA(AS20:BA20)) | BD20: M
B21: 22 | M21: 18 | O21: 18 | Q21: 22 | AB21: Multiplayer | AE21: 3 | AF21: 7 | AG21: 13 | AH21: 16 | AO21: 18 | AT21: 1 | BD21: Multiplayer
A22: =IF(IGRF!B23="","",IGRF!B23) | L22: =IF(COUNTA(B22:J22)=0,"",COUNTA(B22:J22)) | M22: 19 | O22: 19 | P22: =IF(IGRF!I23="","",IGRF!I23) | Q22: D | R22: C | AA22: =IF(COUNTA(Q22:Y22)=0,"",COUNTA(Q22:Y22)) | AB22: C | AC22: =IF(IGRF!B23="","",IGRF!B23) | AD22: C | AN22: =IF(COUNTA(AD22:AL22)=0,"",COUNTA(AD22:AL22)) | AO22: 19 | AR22: =IF(IGRF!I23="","",IGRF!I23) | AU22: P | BC22: =IF(COUNTA(AS22:BA22)=0,"",COUNTA(AS22:BA22)) | BD22: C
M23: 20 | O23: 20 | Q23: 10 | R23: 20 | AB23: Illegal Contact | AD23: 21 | AO23: 20 | AU23: 5 | BD23: Illegal Contact
A24: =IF(IGRF!B24="","",IGRF!B24) | L24: =IF(COUNTA(B24:J24)=0,"",COUNTA(B24:J24)) | M24: 21 | O24: 21 | P24: =IF(IGRF!I24="","",IGRF!I24) | AA24: =IF(COUNTA(Q24:Y24)=0,"",COUNTA(Q24:Y24)) | AB24: Early/Late Hit | AC24: =IF(IGRF!B24="","",IGRF!B24) | AN24: =IF(COUNTA(AD24:AL24)=0,"",COUNTA(AD24:AL24)) | AO24: 21 | AR24: =IF(IGRF!I24="","",IGRF!I24) | AS24: P | AT24: P | BC24: =IF(COUNTA(AS24:BA24)=0,"",COUNTA(AS24:BA24)) | BD24: Early/Late Hit
M25: 22 | O25: 22 | AB25: Out of Play Block | AO25: 22 | AS25: 8 | AT25: 20 | BD25: Out of Play Block
A26: =IF(IGRF!B25="","",IGRF!B25) | L26: =IF(COUNTA(B26:J26)=0,"",COUNTA(B26:J26)) | M26: 23 | O26: 23 | P26: =IF(IGRF!I25="","",IGRF!I25) | Q26: P | R26: B | S26: P | AA26: =IF(COUNTA(Q26:Y26)=0,"",COUNTA(Q26:Y26)) | AB26: D | AC26: =IF(IGRF!B25="","",IGRF!B25) | AN26: =IF(COUNTA(AD26:AL26)=0,"",COUNTA(AD26:AL26)) | AO26: 23 | AR26: =IF(IGRF!I25="","",IGRF!I25) | AV26: F | AW26: B | BC26: =IF(COUNTA(AS26:BA26)=0,"",COUNTA(AS26:BA26)) | BD26: D
M27: 24 | O27: 24 | Q27: 4 | R27: 10 | S27: 22 | AB27: Direction | AO27: 24 | AV27: 11 | AW27: 12 | BD27: Direction
A28: =IF(IGRF!B26="","",IGRF!B26) | L28: =IF(COUNTA(B28:J28)=0,"",COUNTA(B28:J28)) | M28: 25 | O28: 25 | P28: =IF(IGRF!I26="","",IGRF!I26) | AA28: =IF(COUNTA(Q28:Y28)=0,"",COUNTA(Q28:Y28)) | AB28: Stop Block | AC28: =IF(IGRF!B26="","",IGRF!B26) | AN28: =IF(COUNTA(AD28:AL28)=0,"",COUNTA(AD28:AL28)) | AO28: 25 | AR28: =IF(IGRF!I26="","",IGRF!I26) | BC28: =IF(COUNTA(AS28:BA28)=0,"",COUNTA(AS28:BA28)) | BD28: Stop Block
M29: 26 | O29: 26 | AB29: P | AO29: 26 | BD29: P
A30: =IF(IGRF!B27="","",IGRF!B27) | B30: F | C30: L | D30: D | L30: =IF(COUNTA(B30:J30)=0,"",COUNTA(B30:J30)) | M30: 27 | O30: 27 | P30: =IF(IGRF!I27="","",IGRF!I27) | Q30: M | AA30: =IF(COUNTA(Q30:Y30)=0,"",COUNTA(Q30:Y30)) | AB30: Illegal Position | AC30: =IF(IGRF!B27="","",IGRF!B27) | AG30: X | AH30: X | AI30: A | AJ30: C | AM30: FO | AN30: =IF(COUNTA(AD30:AL30)=0,"",COUNTA(AD30:AL30)) | AO30: 27 | AR30: =IF(IGRF!I27="","",IGRF!I27) | AT30: D | BC30: =IF(COUNTA(AS30:BA30)=0,"",COUNTA(AS30:BA30)) | BD30: Illegal Position
B31: 14 | C31: 17 | D31: 19 | M31: 28 | O31: 28 | Q31: 12 | AB31: Destruction | AG31: 3 | AH31: 5 | AI31: 8 | AJ31: 18 | AM31: 18 | AO31: 28 | AT31: 20 | BD31: Destruction
A32: =IF(IGRF!B28="","",IGRF!B28) | L32: =IF(COUNTA(B32:J32)=0,"",COUNTA(B32:J32)) | M32: 29 | O32: 29 | P32: =IF(IGRF!I28="","",IGRF!I28) | Q32: P | R32: D | AA32: =IF(COUNTA(Q32:Y32)=0,"",COUNTA(Q32:Y32)) | AB32: Skating OOB | AC32: =IF(IGRF!B28="","",IGRF!B28) | AN32: =IF(COUNTA(AD32:AL32)=0,"",COUNTA(AD32:AL32)) | AO32: 29 | AR32: =IF(IGRF!I28="","",IGRF!I28) | AU32: P | AV32: D | AW32: M | BC32: =IF(COUNTA(AS32:BA32)=0,"",COUNTA(AS32:BA32)) | BD32: Skating OOB
M33: 30 | O33: 30 | Q33: 5 | R33: 19 | AB33: Failure to Reform | AO33: 30 | AU33: 1 | AV33: 12 | AW33: 16 | BD33: Failure to Reform
A34: =IF(IGRF!B29="","",IGRF!B29) | B34: L | C34: P | D34: P | L34: =IF(COUNTA(B34:J34)=0,"",COUNTA(B34:J34)) | M34: 31 | O34: 31 | P34: =IF(IGRF!I29="","",IGRF!I29) | AA34: =IF(COUNTA(Q34:Y34)=0,"",COUNTA(Q34:Y34)) | AB34: Failure to Return | AC34: =IF(IGRF!B29="","",IGRF!B29) | AG34: D | AN34: =IF(COUNTA(AD34:AL34)=0,"",COUNTA(AD34:AL34)) | AO34: 31 | AR34: =IF(IGRF!I29="","",IGRF!I29) | BC34: =IF(COUNTA(AS34:BA34)=0,"",COUNTA(AS34:BA34)) | BD34: Failure to Return
B35: 10 | C35: 20 | D35: 22 | M35: 32 | O35: 32 | AB35: Failure to Yield | AG35: 12 | AO35: 32 | BD35: Failure to Yield
A36: =IF(IGRF!B30="","",IGRF!B30) | L36: =IF(COUNTA(B36:J36)=0,"",COUNTA(B36:J36)) | M36: 33 | O36: 33 | P36: =IF(IGRF!I30="","",IGRF!I30) | AA36: =IF(COUNTA(Q36:Y36)=0,"",COUNTA(Q36:Y36)) | AB36: X | AC36: =IF(IGRF!B30="","",IGRF!B30) | AD36: X | AE36: X | AF36: F | AN36: =IF(COUNTA(AD36:AL36)=0,"",COUNTA(AD36:AL36)) | AO36: 33 | AR36: =IF(IGRF!I30="","",IGRF!I30) | BC36: =IF(COUNTA(AS36:BA36)=0,"",COUNTA(AS36:BA36)) | BD36: X
M37: 34 | O37: 34 | AB37: Cut | AD37: 3 | AE37: 7 | AF37: 21 | AO37: 34 | BD37: Cut
A38: =IF(IGRF!B31="","",IGRF!B31) | B38: M | C38: F | L38: =IF(COUNTA(B38:J38)=0,"",COUNTA(B38:J38)) | M38: 35 | O38: 35 | P38: =IF(IGRF!I31="","",IGRF!I31) | Q38: P | AA38: =IF(COUNTA(Q38:Y38)=0,"",COUNTA(Q38:Y38)) | AB38: Illegal Re-entry | AC38: =IF(IGRF!B31="","",IGRF!B31) | AN38: =IF(COUNTA(AD38:AL38)=0,"",COUNTA(AD38:AL38)) | AO38: 35 | AR38: =IF(IGRF!I31="","",IGRF!I31) | BC38: =IF(COUNTA(AS38:BA38)=0,"",COUNTA(AS38:BA38)) | BD38: Illegal Re-entry
B39: 10 | C39: 14 | M39: 36 | O39: 36 | Q39: 10 | AB39: N | AO39: 36 | BD39: N
A40: =IF(IGRF!B32="","",IGRF!B32) | L40: =IF(COUNTA(B40:J40)=0,"",COUNTA(B40:J40)) | M40: 37 | O40: 37 | P40: =IF(IGRF!I32="","",IGRF!I32) | AA40: =IF(COUNTA(Q40:Y40)=0,"",COUNTA(Q40:Y40)) | AB40: Interference | AC40: =IF(IGRF!B32="","",IGRF!B32) | AD40: H | AN40: =IF(COUNTA(AD40:AL40)=0,"",COUNTA(AD40:AL40)) | AO40: 37 | AR40: =IF(IGRF!I32="","",IGRF!I32) | BC40: =IF(COUNTA(AS40:BA40)=0,"",COUNTA(AS40:BA40)) | BD40: Interference
...

Sheet Lineups
A1: =Score!$A$1 -> Home Team | H1: =IF(ISBLANK(IGRF!$B$12), "", IGRF!$B$12) | L1: =IF(ISBLANK(IGRF!$B$7), "", IGRF!$B$7) | Z1: 1 | AA1: =Score!T1 -> Away Team | AH1: =IF(ISBLANK(IGRF!$I$12), "", IGRF!$I$12) | AL1: =L1 | AZ1: 1
H2: Color | L2: Date | P2: Lineup Tracker | Z2: =IF(ISBLANK(IGRF!$L$3), "", "GAME " & IGRF!$L$3) | AH2: Color | AL2: Date | AP2: Lineup Tracker | AZ2: =Z2
A3: Jam | B3: noPivot | C3: Jammer | D3: Box | G3: Pivot | H3: Box | K3: Blocker | L3: Box | O3: Blocker | P3: Box | S3: Blocker | T3: Box | X3: Team Roster | AA3: Jam | AB3: noPivot | AC3: Jammer | AD3: Box | AG3: Pivot | AH3: Box | AK3: Blocker | AL3: Box | AO3: Blocker | AP3: Box | AS3: Blocker | AT3: Box | AX3: Team Roster
A4: =IF(Score!A4="", "",Score!A4 ) | C4: =IF(Score!B4="", "",Score!B4 ) | G4: 9 | K4: 518 | O4: 100 | S4: 321 | W4: =IF(A4="","",SUMIF(SK!B$3:B$78,ROW(),SK!D$3:D$78)) | Y4: =IF(IGRF!B14="","",IGRF!B14) | Z4: =IF(IGRF!C14="","",IGRF!C14) | AA4: =IF(Score!T4="", "",Score!T4 ) | AC4: =IF(Score!U4="", "",Score!U4 ) | AG4: 56 | AK4: 1004 | AO4: 13 | AS4: 911 | AW4: =IF(AA4="","",SUMIF(SK!R$3:R$78,ROW(),SK!T$3:T$78)) | AY4: =IF(IGRF!I14="","",IGRF!I14) | AZ4: =IF(IGRF!J14="","",IGRF!J14)
A5: =IF(Score!A5="", "",Score!A5 ) | B5: X | C5: =IF(Score!B5="", "",Score!B5 ) | G5: 33 | K5: 518 | O5: 100 | S5: 321 | W5: =IF(A5="","",SUMIF(SK!B$3:B$78,ROW(),SK!D$3:D$78)) | AA5: =IF(Score!T5="", "",Score!T5 ) | AC5: =IF(Score!U5="", "",Score!U5 ) | AW5: =IF(AA5="","",SUMIF(SK!R$3:R$78,ROW(),SK!T$3:T$78))
A6: =IF(Score!A6="", "",Score!A6 ) | C6: =IF(Score!B6="", "",Score!B6 ) | G6: 10 | H6: - | K6: 0 | O6: 6 | S6: 27 | W6: =IF(A6="","",SUMIF(SK!B$3:B$78,ROW(),SK!D$3:D$78)) | Y6: =IF(IGRF!B15="","",IGRF!B15) | Z6: =IF(IGRF!C15="","",IGRF!C15) | AA6: =IF(Score!T6="", "",Score!T6 ) | AC6: =IF(Score!U6="", "",Score!U6 ) | AG6: 262 | AK6: 113 | AO6: 21 | AS6: 107 | AT6: - | AW6: =IF(AA6="","",SUMIF(SK!R$3:R$78,ROW(),SK!T$3:T$78)) | AY6: =IF(IGRF!I15="","",IGRF!I15) | AZ6: =IF(IGRF!J15="","",IGRF!J15)
A7: =IF(Score!A7="", "",Score!A7 ) | C7: =IF(Score!B7="", "",Score!B7 ) | W7: =IF(A7="","",SUMIF(SK!B$3:B$78,ROW(),SK!D$3:D$78)) | AA7: =IF(Score!T7="", "",Score!T7 ) | AB7: X | AC7: =IF(Score!U7="", "",Score!U7 ) | AG7: 643 | AK7: 113 | AO7: 21 | AS7: 107 | AT7: S | AW7: =IF(AA7="","",SUMIF(SK!R$3:R$78,ROW(),SK!T$3:T$78))
A8: =IF(Score!A8="", "",Score!A8 ) | C8: =IF(Score!B8="", "",Score!B8 ) | G8: 10 | H8: $ | K8: 9 | O8: 518 | S8: 100 | W8: =IF(A8="","",SUMIF(SK!B$3:B$78,ROW(),SK!D$3:D$78)) | Y8: =IF(IGRF!B16="","",IGRF!B16) | Z8: =IF(IGRF!C16="","",IGRF!C16) | AA8: =IF(Score!T8="", "",Score!T8 ) | AC8: =IF(Score!U8="", "",Score!U8 ) | AG8: 56 | AK8: 1004 | AL8: - | AO8: 13 | AP8: - | AS8: 107 | AT8: $ | AW8: =IF(AA8="","",SUMIF(SK!R$3:R$78,ROW(),SK!T$3:T$78)) | AY8: =IF(IGRF!I16="","",IGRF!I16) | AZ8: =IF(IGRF!J16="","",IGRF!J16)
A9: =IF(Score!A9="", "",Score!A9 ) | C9: =IF(Score!B9="", "",Score!B9 ) | G9: 10 | K9: 0 | L9: - | O9: 27 | S9: 6 | W9: =IF(A9="","",SUMIF(SK!B$3:B$78,ROW(),SK!D$3:D$78)) | AA9: =IF(Score!T9="", "",Score!T9 ) | AC9: =IF(Score!U9="", "",Score!U9 ) | AG9: 262 | AH9: - | AK9: 1004 | AL9: S | AO9: 13 | AP9: S | AS9: 113 | AW9: =IF(AA9="","",SUMIF(SK!R$3:R$78,ROW(),SK!T$3:T$78))
A10: =IF(Score!A10="", "",Score!A10 ) | C10: =IF(Score!B10="", "",Score!B10 ) | G10: 321 | K10: 0 | L10: S | O10: 9 | S10: 100 | T10: - | W10: =IF(A10="","",SUMIF(SK!B$3:B$78,ROW(),SK!D$3:D$78)) | Y10: =IF(IGRF!B17="","",IGRF!B17) | Z10: =IF(IGRF!C17="","",IGRF!C17) | AA10: =IF(Score!T10="", "",Score!T10 ) | AC10: =IF(Score!U10="", "",Score!U10 ) | AG10: 262 | AH10: $ | AK10: 1004 | AL10: $ | AO10: 13 | AP10: $ | AS10: 56 | AT10: - | AW10: =IF(AA10="","",SUMIF(SK!R$3:R$78,ROW(),SK!T$3:T$78)) | AY10: =IF(IGRF!I17="","",IGRF!I17) | AZ10: =IF(IGRF!J17="","",IGRF!J17)
A11: =IF(Score!A11="", "",Score!A11 ) | C11: =IF(Score!B11="", "",Score!B11 ) | G11: 6 | K11: 0 | L11: $ | O11: 10 | S11: 100 | T11: $ | W11: =IF(A11="","",SUMIF(SK!B$3:B$78,ROW(),SK!D$3:D$78)) | AA11: =IF(Score!T11="", "",Score!T11 ) | AC11: =IF(Score!U11="", "",Score!U11 ) | AG11: 262 | AK11: 107 | AO11: 113 | AS11: 56 | AT11: $ | AW11: =IF(AA11="","",SUMIF(SK!R$3:R$78,ROW(),SK!T$3:T$78))
A12: =IF(Score!A12="", "",Score!A12 ) | C12: =IF(Score!B12="", "",Score!B12 ) | G12: 321 | K12: 518 | O12: 9 | P12: - | S12: 100 | W12: =IF(A12="","",SUMIF(SK!B$3:B$78,ROW(),SK!D$3:D$78)) | Y12: =IF(IGRF!B18="","",IGRF!B18) | Z12: =IF(IGRF!C18="","",IGRF!C18) | AA12: =IF(Score!T12="", "",Score!T12 ) | AC12: =IF(Score!U12="", "",Score!U12 ) | AG12: 13 | AK12: 221 | AO12: 1004 | AS12: 911 | AW12: =IF(AA12="","",SUMIF(SK!R$3:R$78,ROW(),SK!T$3:T$78)) | AY12: =IF(IGRF!I18="","",IGRF!I18) | AZ12: =IF(IGRF!J18="","",IGRF!J18)
A13: =IF(Score!A13="", "",Score!A13 ) | C13: =IF(Score!B13="", "",Score!B13 ) | G13: 10 | K13: 0 | O13: 9 | P13: $ | S13: 6 | W13: =IF(A13="","",SUMIF(SK!B$3:B$78,ROW(),SK!D$3:D$78)) | AA13: =IF(Score!T13="", "",Score!T13 ) | AC13: =IF(Score!U13="", "",Score!U13 ) | AG13: 262 | AK13: 113 | AO13: 21 | AS13: 107 | AT13: - | AW13: =IF(AA13="","",SUMIF(SK!R$3:R$78,ROW(),SK!T$3:T$78))
A14: =IF(Score!A14="", "",Score!A14 ) | C14: =IF(Score!B14="", "",Score!B14 ) | G14: 321 | K14: 100 | O14: 518 | S14: 9 | W14: =IF(A14="","",SUMIF(SK!B$3:B$78,ROW(),SK!D$3:D$78)) | Y14: =IF(IGRF!B19="","",IGRF!B19) | Z14: =IF(IGRF!C19="","",IGRF!C19) | AA14: =IF(Score!T14="", "",Score!T14 ) | AC14: =IF(Score!U14="", "",Score!U14 ) | AG14: 56 | AK14: 13 | AO14: 1004 | AS14: 107 | AT14: $ | AW14: =IF(AA14="","",SUMIF(SK!R$3:R$78,ROW(),SK!T$3:T$78)) | AY14: =IF(IGRF!I19="","",IGRF!I19) | AZ14: =IF(IGRF!J19="","",IGRF!J19)
A15: =IF(Score!A15="", "",Score!A15 ) | C15: =IF(Score!B15="", "",Score!B15 ) | D15: + | G15: 10 | K15: 0 | L15: + | M15: - | O15: 6 | P15: - | S15: 27 | W15: =IF(A15="","",SUMIF(SK!B$3:B$78,ROW(),SK!D$3:D$78)) | AA15: =IF(Score!T15="", "",Score!T15 ) | AC15: =IF(Score!U15="", "",Score!U15 ) | AD15: - | AG15: 262 | AH15: - | AK15: 21 | AL15: - | AO15: 113 | AS15: 107 | AT15: S | AW15: =IF(AA15="","",SUMIF(SK!R$3:R$78,ROW(),SK!T$3:T$78))
A16: =IF(Score!A16="", "",Score!A16 ) | C16: =IF(Score!B16="", "",Score!B16 ) | W16: =IF(A16="","",SUMIF(SK!B$3:B$78,ROW(),SK!D$3:D$78)) | Y16: =IF(IGRF!B20="","",IGRF!B20) | Z16: =IF(IGRF!C20="","",IGRF!C20) | AA16: =IF(Score!T16="", "",Score!T16 ) | AB16: X | AC16: =IF(Score!U16="", "",Score!U16 ) | AD16: $ | AG16: 643 | AH16: S | AK16: 21 | AL16: S | AO16: 113 | AS16: 107 | AT16: $ | AW16: =IF(AA16="","",SUMIF(SK!R$3:R$78,ROW(),SK!T$3:T$78)) | AY16: =IF(IGRF!I20="","",IGRF!I20) | AZ16: =IF(IGRF!J20="","",IGRF!J20)
A17: =IF(Score!A17="", "",Score!A17 ) | C17: =IF(Score!B17="", "",Score!B17 ) | G17: 10 | K17: 11 | L17: $ | O17: 6 | P17: $ | S17: 100 | W17: =IF(A17="","",SUMIF(SK!B$3:B$78,ROW(),SK!D$3:D$78)) | AA17: =IF(Score!T17="", "",Score!T17 ) | AC17: =IF(Score!U17="", "",Score!U17 ) | AG17: 56 | AK17: 113 | AL17: $ | AO17: 643 | AP17: $ | AS17: 107 | AT17: S | AW17: =IF(AA17="","",SUMIF(SK!R$3:R$78,ROW(),SK!T$3:T$78))
A18: =IF(Score!A18="", "",Score!A18 ) | C18: =IF(Score!B18="", "",Score!B18 ) | G18: 9 | K18: 321 | O18: 518 | S18: 11 | W18: =IF(A18="","",SUMIF(SK!B$3:B$78,ROW(),SK!D$3:D$78)) | Y18: =IF(IGRF!B21="","",IGRF!B21) | Z18: =IF(IGRF!C21="","",IGRF!C21) | AA18: =IF(Score!T18="", "",Score!T18 ) | AC18: =IF(Score!U18="", "",Score!U18 ) | AG18: 262 | AK18: 113 | AO18: 42 | AS18: 107 | AT18: $ | AW18: =IF(AA18="","",SUMIF(SK!R$3:R$78,ROW(),SK!T$3:T$78)) | AY18: =IF(IGRF!I21="","",IGRF!I21) | AZ18: =IF(IGRF!J21="","",IGRF!J21)
A19: =IF(Score!A19="", "",Score!A19 ) | C19: =IF(Score!B19="", "",Score!B19 ) | G19: 10 | K19: 6 | O19: 0 | P19: - | S19: 27 | W19: =IF(A19="","",SUMIF(SK!B$3:B$78,ROW(),SK!D$3:D$78)) | AA19: =IF(Score!T19="", "",Score!T19 ) | AC19: =IF(Score!U19="", "",Score!U19 ) | AG19: 56 | AK19: 13 | AO19: 42 | AP19: $ | AS19: 1004 | AW19: =IF(AA19="","",SUMIF(SK!R$3:R$78,ROW(),SK!T$3:T$78))
A20: =IF(Score!A20="", "",Score!A20 ) | B20: X | C20: =IF(Score!B20="", "",Score!B20 ) | G20: 33 | K20: 6 | O20: 0 | P20: S | S20: 27 | W20: =IF(A20="","",SUMIF(SK!B$3:B$78,ROW(),SK!D$3:D$78)) | Y20: =IF(IGRF!B22="","",IGRF!B22) | Z20: =IF(IGRF!C22="","",IGRF!C22) | AA20: =IF(Score!T20="", "",Score!T20 ) | AC20: =IF(Score!U20="", "",Score!U20 ) | AW20: =IF(AA20="","",SUMIF(SK!R$3:R$78,ROW(),SK!T$3:T$78)) | AY20: =IF(IGRF!I22="","",IGRF!I22) | AZ20: =IF(IGRF!J22="","",IGRF!J22)
A21: =IF(Score!A21="", "",Score!A21 ) | C21: =IF(Score!B21="", "",Score!B21 ) | D21: + | G21: 9 | K21: 518 | L21: - | O21: 0 | P21: $ | S21: 100 | W21: =IF(A21="","",SUMIF(SK!B$3:B$78,ROW(),SK!D$3:D$78)) | AA21: =IF(Score!T21="", "",Score!T21 ) | AC21: =IF(Score!U21="", "",Score!U21 ) | AG21: 262 | AK21: 113 | AO21: 21 | AS21: 59 | AW21: =IF(AA21="","",SUMIF(SK!R$3:R$78,ROW(),SK!T$3:T$78))
A22: =IF(Score!A22="", "",Score!A22 ) | C22: =IF(Score!B22="", "",Score!B22 ) | G22: 10 | H22: - | K22: 518 | L22: $ | O22: 6 | S22: 321 | W22: =IF(A22="","",SUMIF(SK!B$3:B$78,ROW(),SK!D$3:D$78)) | Y22: =IF(IGRF!B23="","",IGRF!B23) | Z22: =IF(IGRF!C23="","",IGRF!C23) | AA22: =IF(Score!T22="", "",Score!T22 ) | AC22: =IF(Score!U22="", "",Score!U22 ) | AG22: 56 | AK22: 1004 | AL22: - | AO22: 221 | AS22: 13 | AT22: - | AW22: =IF(AA22="","",SUMIF(SK!R$3:R$78,ROW(),SK!T$3:T$78)) | AY22: =IF(IGRF!I23="","",IGRF!I23) | AZ22: =IF(IGRF!J23="","",IGRF!J23)
A23: =IF(Score!A23="", "",Score!A23 ) | C23: =IF(Score!B23="", "",Score!B23 ) | W23: =IF(A23="","",SUMIF(SK!B$3:B$78,ROW(),SK!D$3:D$78)) | AA23: =IF(Score!T23="", "",Score!T23 ) | AB23: X | AC23: =IF(Score!U23="", "",Score!U23 ) | AG23: 63 | AK23: 1004 | AL23: S | AO23: 221 | AS23: 13 | AT23: S | AW23: =IF(AA23="","",SUMIF(SK!R$3:R$78,ROW(),SK!T$3:T$78))
A24: =IF(Score!A24="", "",Score!A24 ) | C24: =IF(Score!B24="", "",Score!B24 ) | G24: 10 | H24: $ | K24: 100 | S24: 321 | W24: =IF(A24="","",SUMIF(SK!B$3:B$78,ROW(),SK!D$3:D$78)) | Y24: =IF(IGRF!B24="","",IGRF!B24) | Z24: =IF(IGRF!C24="","",IGRF!C24) | AA24: =IF(Score!T24="", "",Score!T24 ) | AC24: =IF(Score!U24="", "",Score!U24 ) | AG24: 262 | AK24: 1004 | AL24: $ | AO24: 113 | AS24: 13 | AT24: $ | AW24: =IF(AA24="","",SUMIF(SK!R$3:R$78,ROW(),SK!T$3:T$78)) | AY24: =IF(IGRF!I24="","",IGRF!I24) | AZ24: =IF(IGRF!J24="","",IGRF!J24)
A25: =IF(Score!A25="", "",Score!A25 ) | C25: =IF(Score!B25="", "",Score!B25 ) | G25: 10 | K25: 518 | L25: - | O25: 27 | P25: - | S25: 6 | W25: =IF(A25="","",SUMIF(SK!B$3:B$78,ROW(),SK!D$3:D$78)) | AA25: =IF(Score!T25="", "",Score!T25 ) | AC25: =IF(Score!U25="", "",Score!U25 ) | AG25: 56 | AK25: 1004 | AO25: 911 | AS25: 13 | AW25: =IF(AA25="","",SUMIF(SK!R$3:R$78,ROW(),SK!T$3:T$78))
A26: =IF(Score!A26="", "",Score!A26 ) | C26: =IF(Score!B26="", "",Score!B26 ) | G26: 10 | K26: 518 | L26: $ | O26: 27 | P26: $ | S26: 100 | W26: =IF(A26="","",SUMIF(SK!B$3:B$78,ROW(),SK!D$3:D$78)) | Y26: =IF(IGRF!B25="","",IGRF!B25) | Z26: =IF(IGRF!C25="","",IGRF!C25) | AA26: =IF(Score!T26="", "",Score!T26 ) | AC26: =IF(Score!U26="", "",Score!U26 ) | AG26: 262 | AK26: 42 | AO26: 113 | AS26: 21 | AW26: =IF(AA26="","",SUMIF(SK!R$3:R$78,ROW(),SK!T$3:T$78)) | AY26: =IF(IGRF!I25="","",IGRF!I25) | AZ26: =IF(IGRF!J25="","",IGRF!J25)
A27: =IF(Score!A27="", "",Score!A27 ) | C27: =IF(Score!B27="", "",Score!B27 ) | G27: 321 | K27: 9 | O27: 518 | P27: + | S27: 100 | W27: =IF(A27="","",SUMIF(SK!B$3:B$78,ROW(),SK!D$3:D$78)) | AA27: =IF(Score!T27="", "",Score!T27 ) | AC27: =IF(Score!U27="", "",Score!U27 ) | AG27: 56 | AH27: - | AK27: 1004 | AL27: - | AO27: 113 | AP27: $ | AS27: 13 | AW27: =IF(AA27="","",SUMIF(SK!R$3:R$78,ROW(),SK!T$3:T$78))
A28: =IF(Score!A28="", "",Score!A28 ) | C28: =IF(Score!B28="", "",Score!B28 ) | G28: 10 | H28: - | K28: 11 | O28: 6 | P28: + | Q28: - | S28: 579 | W28: =IF(A28="","",SUMIF(SK!B$3:B$78,ROW(),SK!D$3:D$78)) | Y28: =IF(IGRF!B26="","",IGRF!B26) | Z28: =IF(IGRF!C26="","",IGRF!C26) | AA28: =IF(Score!T28="", "",Score!T28 ) | AC28: =IF(Score!U28="", "",Score!U28 ) | AG28: 56 | AH28: $ | AK28: 1004 | AL28: $ | AO28: 262 | AS28: 21 | AT28: - | AW28: =IF(AA28="","",SUMIF(SK!R$3:R$78,ROW(),SK!T$3:T$78)) | AY28: =IF(IGRF!I26="","",IGRF!I26) | AZ28: =IF(IGRF!J26="","",IGRF!J26)
A29: =IF(Score!A29="", "",Score!A29 ) | C29: =IF(Score!B29="", "",Score!B29 ) | G29: 10 | H29: $ | K29: 100 | O29: 6 | P29: $ | S29: 9 | W29: =IF(A29="","",SUMIF(SK!B$3:B$78,ROW(),SK!D$3:D$78)) | AA29: =IF(Score!T29="", "",Score!T29 ) | AC29: =IF(Score!U29="", "",Score!U29 ) | AG29: 56 | AK29: 911 | AO29: 13 | AS29: 21 | AT29: $ | AW29: =IF(AA29="","",SUMIF(SK!R$3:R$78,ROW(),SK!T$3:T$78))
A30: =IF(Score!A30="", "",Score!A30 ) | C30: =IF(Score!B30="", "",Score!B30 ) | G30: 10 | K30: 0 | O30: 6 | P30: - | S30: 321 | T30: - | W30: =IF(A30="","",SUMIF(SK!B$3:B$78,ROW(),SK!D$3:D$78)) | Y30: =IF(IGRF!B27="","",IGRF!B27) | Z30: =IF(IGRF!C27="","",IGRF!C27) | AA30: =IF(Score!T30="", "",Score!T30 ) | AC30: =IF(Score!U30="", "",Score!U30 ) | AD30: - | AG30: 113 | AH30: - | AK30: 42 | AO30: 107 | AP30: - | AS30: 262 | AT30: - | AW30: =IF(AA30="","",SUMIF(SK!R$3:R$78,ROW(),SK!T$3:T$78)) | AY30: =IF(IGRF!I27="","",IGRF!I27) | AZ30: =IF(IGRF!J27="","",IGRF!J27)
A31: =IF(Score!A31="", "",Score!A31 ) | C31: =IF(Score!B31="", "",Score!B31 ) | W31: =IF(A31="","",SUMIF(SK!B$3:B$78,ROW(),SK!D$3:D$78)) | AA31: =IF(Score!T31="", "",Score!T31 ) | AC31: =IF(Score!U31="", "",Score!U31 ) | AW31: =IF(AA31="","",SUMIF(SK!R$3:R$78,ROW(),SK!T$3:T$78))
A32: =IF(Score!A32="", "",Score!A32 ) | C32: =IF(Score!B32="", "",Score!B32 ) | W32: =IF(A32="","",SUMIF(SK!B$3:B$78,ROW(),SK!D$3:D$78)) | Y32: =IF(IGRF!B28="","",IGRF!B28) | Z32: =IF(IGRF!C28="","",IGRF!C28) | AA32: =IF(Score!T32="", "",Score!T32 ) | AC32: =IF(Score!U32="", "",Score!U32 ) | AW32: =IF(AA32="","",SUMIF(SK!R$3:R$78,ROW(),SK!T$3:T$78)) | AY32: =IF(IGRF!I28="","",IGRF!I28) | AZ32: =IF(IGRF!J28="","",IGRF!J28)
A33: =IF(Score!A33="", "",Score!A33 ) | C33: =IF(Score!B33="", "",Score!B33 ) | W33: =IF(A33="","",SUMIF(SK!B$3:B$78,ROW(),SK!D$3:D$78)) | AA33: =IF(Score!T33="", "",Score!T33 ) | AC33: =IF(Score!U33="", "",Score!U33 ) | AW33: =IF(AA33="","",SUMIF(SK!R$3:R$78,ROW(),SK!T$3:T$78))
A34: =IF(Score!A34="", "",Score!A34 ) | C34: =IF(Score!B34="", "",Score!B34 ) | W34: =IF(A34="","",SUMIF(SK!B$3:B$78,ROW(),SK!D$3:D$78)) | Y34: =IF(IGRF!B29="","",IGRF!B29) | Z34: =IF(IGRF!C29="","",IGRF!C29) | AA34: =IF(Score!T34="", "",Score!T34 ) | AC34: =IF(Score!U34="", "",Score!U34 ) | AW34: =IF(AA34="","",SUMIF(SK!R$3:R$78,ROW(),SK!T$3:T$78)) | AY34: =IF(IGRF!I29="","",IGRF!I29) | AZ34: =IF(IGRF!J29="","",IGRF!J29)
A35: =IF(Score!A35="", "",Score!A35 ) | C35: =IF(Score!B35="", "",Score!B35 ) | W35: =IF(A35="","",SUMIF(SK!B$3:B$78,ROW(),SK!D$3:D$78)) | AA35: =IF(Score!T35="", "",Score!T35 ) | AC35: =IF(Score!U35="", "",Score!U35 ) | AW35: =IF(AA35="","",SUMIF(SK!R$3:R$78,ROW(),SK!T$3:T$78))
A36: =IF(Score!A36="", "",Score!A36 ) | C36: =IF(Score!B36="", "",Score!B36 ) | W36: =IF(A36="","",SUMIF(SK!B$3:B$78,ROW(),SK!D$3:D$78)) | Y36: =IF(IGRF!B30="","",IGRF!B30) | Z36: =IF(IGRF!C30="","",IGRF!C30) | AA36: =IF(Score!T36="", "",Score!T36 ) | AC36: =IF(Score!U36="", "",Score!U36 ) | AW36: =IF(AA36="","",SUMIF(SK!R$3:R$78,ROW(),SK!T$3:T$78)) | AY36: =IF(IGRF!I30="","",IGRF!I30) | AZ36: =IF(IGRF!J30="","",IGRF!J30)
A37: =IF(Score!A37="", "",Score!A37 ) | C37: =IF(Score!B37="", "",Score!B37 ) | W37: =IF(A37="","",SUMIF(SK!B$3:B$78,ROW(),SK!D$3:D$78)) | AA37: =IF(Score!T37="", "",Score!T37 ) | AC37: =IF(Score!U37="", "",Score!U37 ) | AW37: =IF(AA37="","",SUMIF(SK!R$3:R$78,ROW(),SK!T$3:T$78))
A38: =IF(Score!A38="", "",Score!A38 ) | C38: =IF(Score!B38="", "",Score!B38 ) | W38: =IF(A38="","",SUMIF(SK!B$3:B$78,ROW(),SK!D$3:D$78)) | Y38: =IF(IGRF!B31="","",IGRF!B31) | Z38: =IF(IGRF!C31="","",IGRF!C31) | AA38: =IF(Score!T38="", "",Score!T38 ) | AC38: =IF(Score!U38="", "",Score!U38 ) | AW38: =IF(AA38="","",SUMIF(SK!R$3:R$78,ROW(),SK!T$3:T$78)) | AY38: =IF(IGRF!I31="","",IGRF!I31) | AZ38: =IF(IGRF!J31="","",IGRF!J31)
A39: =IF(Score!A39="", "",Score!A39 ) | C39: =IF(Score!B39="", "",Score!B39 ) | W39: =IF(A39="","",SUMIF(SK!B$3:B$78,ROW(),SK!D$3:D$78)) | AA39: =IF(Score!T39="", "",Score!T39 ) | AC39: =IF(Score!U39="", "",Score!U39 ) | AW39: =IF(AA39="","",SUMIF(SK!R$3:R$78,ROW(),SK!T$3:T$78))
A40: =IF(Score!A40="", "",Score!A40 ) | C40: =IF(Score!B40="", "",Score!B40 ) | W40: =IF(A40="","",SUMIF(SK!B$3:B$78,ROW(),SK!D$3:D$78)) | Y40: =IF(IGRF!B32="","",IGRF!B32) | Z40: =IF(IGRF!C32="","",IGRF!C32) | AA40: =IF(Score!T40="", "",Score!T40 ) | AC40: =IF(Score!U40="", "",Score!U40 ) | AW40: =IF(AA40="","",SUMIF(SK!R$3:R$78,ROW(),SK!T$3:T$78)) | AY40: =IF(IGRF!I32="","",IGRF!I32) | AZ40: =IF(IGRF!J32="","",IGRF!J32)
...

Sheet Penalties-Lineups
A1: =Score!$A$1 -> Home Team | K1: =IF(ISBLANK(IGRF!$B$12), "", IGRF!$B$12) | P1: =IF(ISBLANK(IGRF!$B$7), "", IGRF!$B$7) | AF1: 1 | AJ1: =Score!T1 -> Away Team | AT1: =IF(ISBLANK(IGRF!$I$12), "", IGRF!$I$12) | AY1: =P1 | BO1: 1
K2: Color | P2: Date | T2: Penalty-Lineup Tracker | AF2: =IF(ISBLANK(IGRF!$L$3), "", "GAME " & IGRF!$L$3) | AT2: Color | AY2: Date | BC2: Penalty-Lineup Tracker | BO2: =AF2
A3: Jam | B3: noPivot | C3: Jammer | D3: Box | G3: Pivot | H3: Box | K3: Blocker | L3: Box | O3: Blocker | P3: Box | S3: Blocker | T3: Box | X3: Roster | Y3: Penalties | AH3: FO/EXP | AJ3: Jam | AK3: noPivot | AL3: Jammer | AM3: Box | AP3: Pivot | AQ3: Box | AT3: Blocker | AU3: Box | AX3: Blocker | AY3: Box | BB3: Blocker | BC3: Box | BG3: Roster | BH3: Penalties | BQ3: FO/EXP
X4: =IF(IGRF!B14="","",IGRF!B14) | BG4: =IF(IGRF!I14="","",IGRF!I14)
X6: =IF(IGRF!B15="","",IGRF!B15) | BG6: =IF(IGRF!I15="","",IGRF!I15)
X8: =IF(IGRF!B16="","",IGRF!B16) | BG8: =IF(IGRF!I16="","",IGRF!I16)
X10: =IF(IGRF!B17="","",IGRF!B17) | BG10: =IF(IGRF!I17="","",IGRF!I17)
X12: =IF(IGRF!B18="","",IGRF!B18) | BG12: =IF(IGRF!I18="","",IGRF!I18)
X14: =IF(IGRF!B19="","",IGRF!B19) | BG14: =IF(IGRF!I19="","",IGRF!I19)
X16: =IF(IGRF!B20="","",IGRF!B20) | BG16: =IF(IGRF!I20="","",IGRF!I20)
X18: =IF(IGRF!B21="","",IGRF!B21) | BG18: =IF(IGRF!I21="","",IGRF!I21)
X20: =IF(IGRF!B22="","",IGRF!B22) | BG20: =IF(IGRF!I22="","",IGRF!I22)
X22: =IF(IGRF!B23="","",IGRF!B23) | BG22: =IF(IGRF!I23="","",IGRF!I23)
X24: =IF(IGRF!B24="","",IGRF!B24) | BG24: =IF(IGRF!I24="","",IGRF!I24)
X26: =IF(IGRF!B25="","",IGRF!B25) | BG26: =IF(IGRF!I25="","",IGRF!I25)
X28: =IF(IGRF!B26="","",IGRF!B26) | BG28: =IF(IGRF!I26="","",IGRF!I26)
X30: =IF(IGRF!B27="","",IGRF!B27) | BG30: =IF(IGRF!I27="","",IGRF!I27)
X32: =IF(IGRF!B28="","",IGRF!B28) | BG32: =IF(IGRF!I28="","",IGRF!I28)
X34: =IF(IGRF!B29="","",IGRF!B29) | BG34: =IF(IGRF!I29="","",IGRF!I29)
X36: =IF(IGRF!B30="","",IGRF!B30) | BG36: =IF(IGRF!I30="","",IGRF!I30)
X38: =IF(IGRF!B31="","",IGRF!B31) | BG38: =IF(IGRF!I31="","",IGRF!I31)
X40: =IF(IGRF!B32="","",IGRF!B32) | BG40: =IF(IGRF!I32="","",IGRF!I32)
A42: Box Codes: – = Entered the box mid-jam. S = Entered between jams or continued from previous jam. | = Finished service. Combined with - and S, creates + and $. 3 = Skater injured or needed sub, sits out 3 jams. Penalty Codes: G = (Gross) Misconduct/Insub. | A = High Block, B = Back Block, L = Low Block | E = Leg Block, F = Forearms, H = Head Block, M = Multiplayer | C = Illegal Contact/Early or Late Hit/Out of Play Block, D = Direction/Stop Block | P = Illegal Position/Destruction/Skating OOB/Failure to Reform/Return/Yield | X = Cut | N = Interference/Delay of Game | I = Illegal Procedure/Star Pass Violation/Star Pass Interference | S42: Non-Skater Expulsions | X42: =IF(IGRF!B33="","",IGRF!B33) | AJ42: Box Codes: – = Entered the box mid-jam. S = Entered between jams or continued from previous jam. | = Finished service. Combined with - and S, creates + and $. 3 = Skater injured or needed sub, sits out 3 jams. Penalty Codes: G = (Gross) Misconduct/Insub. | A = High Block, B = Back Block, L = Low Block | E = Leg Block, F = Forearms, H = Head Block, M = Multiplayer | C = Illegal Contact/Early or Late Hit/Out of Play Block, D = Direction/Stop Block | P = Illegal Position/Destruction/Skating OOB/Failure to Reform/Return/Yield | X = Cut | N = Interference/Delay of Game | I = Illegal Procedure/Star Pass Violation/Star Pass Interference | BB42: Non-Skater Expulsions | BG42: =IF(IGRF!I33="","",IGRF!I33)
AC44: Total Penalties for Period 1: | BL44: Total Penalties for Period 1:
A45: =A1 -> Home Team | K45: =K1 | P45: =P1 | AF45: 2 | AJ45: =AJ1 -> Away Team | AT45: =AT1 | AY45: =AY1 | BO45: 2
K46: Color | P46: Date | T46: Penalty-Lineup Tracker | AF46: =AF2 | AT46: Color | AY46: Date | BC46: Penalty-Lineup Tracker | BO46: =BO2
A47: Jam | B47: noPivot | C47: Jammer | D47: Box | G47: Pivot | H47: Box | K47: Blocker | L47: Box | O47: Blocker | P47: Box | S47: Blocker | T47: Box | X47: Roster | Y47: Penalties | AH47: FO/EXP | AJ47: Jam | AK47: noPivot | AL47: Jammer | AM47: Box | AP47: Pivot | AQ47: Box | AT47: Blocker | AU47: Box | AX47: Blocker | AY47: Box | BB47: Blocker | BC47: Box | BG47: Roster | BH47: Penalties | BQ47: FO/EXP
X48: =X4 | BG48: =BG4
X50: =X6 | BG50: =BG6
X52: =X8 | BG52: =BG8
X54: =X10 | BG54: =BG10
X56: =X12 | BG56: =BG12
X58: =X14 | BG58: =BG14
X60: =X16 | BG60: =BG16
X62: =X18 | BG62: =BG18
X64: =X20 | BG64: =BG20
X66: =X22 | BG66: =BG22
X68: =X24 | BG68: =BG24
X70: =X26 | BG70: =BG26
... X84: =X40 | BG84: =BG40
...

Sheet Expulsion-Suspension Form
A1: This form should be completed and signed for any expulsion in a game. Statements are not required and may be continued on the reverse side. All signatures certify receipt of the form and one's own statement; it does not express agreement with the statement(s) of others. Any party who may, and chooses to, recommend a suspension should check the appropriate box next to their E-Mail Address.
A3: For WFTDA-sanctioned games, the expulsion must be recorded on the IGRF in the appropriate section. Return signed and completed Expulsion/Suspension forms to WFTDA Sanctioning with the completed StatsBook and signed IGRF. These will be filed with the game documentation. If any party wishes to have an incident reviewed by the Games Review Panel (GRP), indicate this on the IGRF at the time of signature. Any appeals may be filed with the WFTDA GRP at grievance@wftda.com.
A5: Game Date: | B5: =IF(ISBLANK(IGRF!$B$7), "", IGRF!$B$7) | C5: Teams Participating: | D5: =IF(IGRF!B10="","",IGRF!$B$10&" / "&IGRF!$B$11&IF(IGRF!B12="",""," ("&IGRF!$B$12&")")&" vs. "&IGRF!$I$10&" / "&IGRF!$I$11&IF(IGRF!I12="",""," ("&IGRF!$I$12&")"))
A6: Suspension Recommended Below: | B6: YES | NO | C6: Meeting Results (if held):
A8: Name of Official Witnessing the Action: | C8: Signature:
A9: Official's Legal Name: | C9: League Affiliation: | E9: Penalty Issued:
A10: Official's E-Mail Address:
A11: Incident:
A13: Head Referee Name: | B13: =IF(ISBLANK(IGRF!C80), "", IGRF!C80) | C13: Signature:
A14: Head Referee's Legal Name: | C14: League Affiliation: | D14: =IF(ISBLANK(IGRF!H80),"",IGRF!H80) | E14: Suspension Recommended:
A15: Head Referee's E-Mail Address: | E15: YES | NO
A16: Comments:
A18: Expelled Skater: | C18: Signature:
A19: Skater's Legal Name: | C19: League Affiliation:
A20: Skater's E-Mail Address:
A21: Comments:
A23: =IF(ISBLANK(IGRF!$B$11), "Home/Dark Team Captain Name: ", IGRF!$B$11&" Captain Name: ") -> Home/Dark Team Captain Name: | B23: =IF(ISBLANK(IGRF!B49),"",IGRF!B49) | C23: Signature:
A24: Captain's Legal Name: | C24: League Affiliation: | D24: =IF(ISBLANK(IGRF!$B$10), "", IGRF!$B$10) | E24: Suspension Recommended:
A25: Captain's E-Mail Address: | E25: YES | NO
A26: Comments:
A28: =IF(ISBLANK(IGRF!$I$11), "Away/Light Team Captain Name: ", IGRF!$I$11&" Captain Name: ") -> Away/Light Team Captain Name: | B28: =IF(ISBLANK(IGRF!I49), "", IGRF!I49) | C28: Signature:
A29: Captain's Legal Name: | C29: League Affiliation: | D29: =IF(ISBLANK(IGRF!$I$10), "", IGRF!$I$10) | E29: Suspension Recommended:
A30: Captain's E-Mail Address: | E30: YES | NO
A31: Comments:
A33: FOR TOURNAMENT PLAY
A35: Tournament Head Referee Name: | C35: Signature:
A36: THR's Legal Name: | C36: League Affiliation: | E36: Suspension Recommended:
A37: THR's E-Mail Address: | E37: YES | NO
A38: Comments:
A40: GTO Name (if present): | C40: Signature:
A41: GTO's Legal Name: | C41: League Affiliation: | E41: Suspension Recommended:
A42: GTO's E-Mail Address: | E42: YES | NO
A43: Comments:

Sheet Game Summary
A1: W F T D A R E Q U I R E D S T A N D A R D I Z E D S T A T S
A2: =IF(IGRF!B10="","PLEASE FILL IN THE IGRF TAB!",IGRF!$B$10&" / "&IGRF!$B$11&" vs. "&IGRF!$I$10&" / "&IGRF!$I$11&IF(IGRF!$L$3="",""," Game "&IGRF!$L$3)) -> PLEASE FILL IN THE IGRF TAB!
A3: =IF(IGRF!$B$7="","ENTER DATE ON IGRF TAB!",IGRF!$B$7) -> ENTER DATE ON IGRF TAB!
A4: ROSTERS | C4: JAMS PLAYED | J4: LEAD JAMMER | R4: POINTS FOR/AGAINST & PLUS/MINUS | AD4: V.T.A.R. | AL4: PENALTIES
A5: # | B5: =Score!$A$1 -> Home Team | C5: JAMMER | D5: PIVOT | E5: BLOCKER | F5: TOTAL | G5: % JAMS SKATED | H5: POINTS | I5: PPJ | J5: LOST | K5: LEAD | L5: CALLED | M5: NO INITIAL TRIP | N5: STAR PASSES RECEIVED | O5: LEAD % | P5: LEAD +/- | Q5: AVERAGE LEAD +/- | R5: PTS FOR | S5: PTS AGAINST | T5: TOTAL +/- | U5: JAMMER +/- | V5: AVERAGE JAMMER +/- | W5: PIVOT +/- | X5: AVERAGE PIVOT +/- | Y5: BLOCK +/- | Z5: AVERAGE BLOCKER +/- | AA5: PACK +/- | AB5: AVERAGE PACK +/- | AC5: AVG +/- | AD5: VTAR PTS FOR | AE5: VTAR PTS AGAINST | AF5: VTAR TOTAL +/- | AG5: VTAR JAMMER AVG +/- | AH5: VTAR PIVOT AVG +/- | AI5: VTAR BLOCKER AVG +/- | AJ5: VTAR PACK AVG +/- | AK5: TOTAL VTAR AVG +/- | AL5: SKATERS PENALTY COUNT
